try {
    let a = 3;
    console.log(a)
}catch(err){
    console.log('let перед использованием нужно объявить')
}
